Workbook

Sheet Supuestos
A1: Modelo financiero ERV — Vox-Causal AI en Alloxentric SpA (GBP, 36 meses, flujos a fin de mes)
A2: Verde = dato del caso. Amarillo = supuesto de modelación (ver columna Fuente). Cambie las celdas para recalcular.
A4: Parámetro | B4: Optimista | C4: Base | D4: Pesimista | E4: Unidad | F4: Fuente / justificación
A5: Horas-hombre de integración | B5: 800 | C5: 800 | D5: 1000 | E5: HH | F5: Caso PIA (800 HH); pesimista +25 % de desvío
A6: Tarifa diaria de ingeniería MLOps | B6: 425 | C6: 550 | D6: 775 | E6: £/día | F6: itjobswatch UK MLOps (6 meses a 27-10-2026): p10 £425, mediana £550, p90 £775
A7: Reducción del TTR | B7: 0.15 | C7: 0.15 | D7: 0.15 | E7: fracción | F7: Caso PIA (15 %)
A8: Recargo sobre suscripción | B8: 0.2 | C8: 0.2 | D8: 0.2 | E8: fracción | F8: Caso PIA (20 %)
A9: Llamadas concurrentes objetivo | B9: 1500 | C9: 1500 | D9: 1500 | E9: llamadas | F9: Caso PIA (KPI 1.500)
A10: Reserva de contingencia sobre el CAPEX | B10: 0.1 | C10: 0.1 | D10: 0.1 | E10: fracción | F10: Supuesto: 10 % del BAC (línea base EVM del caso)
A11: CAPEX ejecutado en el mes 1 | B11: 0.3533 | C11: 0.3533 | D11: 0.3533 | E11: fracción | F11: PV acumulada del EVM a la semana 4 (35,33 %)
A12: CAPEX ejecutado en el mes 2 | B12: 0.4342 | C12: 0.4342 | D12: 0.4342 | E12: fracción | F12: PV semanas 5-8 del EVM (43,42 %)
A13: CAPEX ejecutado en el mes 3 | B13: 0.2125 | C13: 0.2125 | D13: 0.2125 | E13: fracción | F13: PV semanas 9-12 del EVM (21,25 %)
A14: Mes de puesta en producción | B14: 4 | C14: 4 | D14: 7 | E14: mes | F14: Supuesto: integración de 12 semanas (meses 1-3)
A15: Inicio de la adopción comercial | B15: 4 | C15: 4 | D15: 7 | E15: mes | F15: Supuesto
A16: Fin de la rampa de adopción | B16: 12 | C16: 15 | D16: 24 | E16: mes | F16: Supuesto: lineal de 10 % a 100 % del objetivo
... A41: Tasa de descuento anual | B41: 0.12 | C41: 0.12 | D41: 0.12 | E41: fracción | F41: Damodaran ene-2026, Europa, Software (System & Application) 8,70 % + 3,3 pp
A43: Derivados
A44: Tarifa por hora (día de 7,5 h) | B44: =(B6)/7.5 -> 56.666667 | C44: =(C6)/7.5 -> 73.333333 | D44: =(D6)/7.5 -> 103.33333 | E44: £/h
A45: CAPEX total (con reserva) | B45: =B5*B44*(1+B10) -> 49866.667 | C45: =C5*C44*(1+C10) -> 64533.333 | D45: =D5*D44*(1+D10) -> 113666.67 | E45: £
A46: Llamadas/mes con 100 % de los puestos | B46: =B9*(B20+B21)*(60/B22)*365 -> 2137744 | C46: =C9*(C20+C21)*(60/C22)*365 -> 2137744 | D46: =D9*(D20+D21)*(60/D22)*365 -> 2137744 | E46: llamadas
A47: Réplicas en el pico de 1.500 llamadas | B47: =MAX(B25,CEILING(B9/B23,1)+B24) -> 10 | C47: =MAX(C25,CEILING(C9/C23,1)+C24) -> 10 | D47: =MAX(D25,CEILING(D9/D23,1)+D24) -> 16 | E47: réplicas
A48: Precio por réplica-hora | B48: =3600*(B26*'Precios Azure'!$C$3+B27*'Precios Azure'!$C$4) -> 0.11411366 | C48: =3600*(C26*'Precios Azure'!$C$3+C27*'Precios Azure'!$C$4) -> 0.11411366 | D48: =3600*(D26*'Precios Azure'!$C$3+D27*'Precios Azure'!$C$4) -> 0.11411366 | E48: £/h
A49: Tasa de descuento mensual | B49: =(1+B41)^(1/12)-1 -> 0.0094887929 | C49: =(1+C41)^(1/12)-1 -> 0.0094887929 | D49: =(1+D41)^(1/12)-1 -> 0.0094887929 | E49: fracción

Sheet Resultados
A1: Indicador | B1: Optimista | C1: Base | D1: Pesimista | E1: Fórmula
A2: CAPEX (£) | B2: =Supuestos!B45 -> 49866.667 | C2: =Supuestos!C45 -> 64533.333 | D2: =Supuestos!D45 -> 113666.67 | E2: HH × tarifa por hora
A3: VAN 36 meses (£) | B3: =NPV(Supuestos!B49,'Flujo Optimista'!U2:U37) -> 453907.57 | C3: =NPV(Supuestos!C49,'Flujo Base'!U2:U37) -> 174125.2 | D3: =NPV(Supuestos!D49,'Flujo Pesimista'!U2:U37) -> -184677.47 | E3: VNA(tasa mensual; flujos netos meses 1-36)
A4: TIR mensual | B4: =IFERROR(IRR('Flujo Optimista'!U2:U37),"No existe") -> 0.18188952 | C4: =IFERROR(IRR('Flujo Base'!U2:U37),"No existe") -> 0.083037089 | D4: =IFERROR(IRR('Flujo Pesimista'!U2:U37),"No existe") -> No existe | E4: TIR de los flujos mensuales
A5: TIR anual equivalente | B5: =IFERROR((1+IRR('Flujo Optimista'!U2:U37))^12-1,"No existe") -> 6.4288673 | C5: =IFERROR((1+IRR('Flujo Base'!U2:U37))^12-1,"No existe") -> 1.6044736 | D5: =IFERROR((1+IRR('Flujo Pesimista'!U2:U37))^12-1,"No existe") -> No existe | E5: (1+TIR mensual)^12 − 1
A6: Mes de recuperación (payback simple) | B6: =IFERROR(INDEX('Flujo Optimista'!A2:A37,MATCH(TRUE,INDEX('Flujo Optimista'!V2:V37>=0,0),0)),"No recupera") -> 10 | C6: =IFERROR(INDEX('Flujo Base'!A2:A37,MATCH(TRUE,INDEX('Flujo Base'!V2:V37>=0,0),0)),"No recupera") -> 16 | D6: =IFERROR(INDEX('Flujo Pesimista'!A2:A37,MATCH(TRUE,INDEX('Flujo Pesimista'!V2:V37>=0,0),0)),"No recupera") -> No recupera | E6: Primer mes con flujo acumulado ≥ 0
A7: VP ingresos (£) | B7: =NPV(Supuestos!B49,'Flujo Optimista'!T2:T37) -> 566766.67 | C7: =NPV(Supuestos!C49,'Flujo Base'!T2:T37) -> 322423.37 | D7: =NPV(Supuestos!D49,'Flujo Pesimista'!T2:T37) -> 69417.116
A8: VP costos CAPEX + OPEX (£) | B8: =NPV(Supuestos!B49,'Flujo Optimista'!B2:B37)+NPV(Supuestos!B49,'Flujo Optimista'!S2:S37) -> 112859.1 | C8: =NPV(Supuestos!C49,'Flujo Base'!B2:B37)+NPV(Supuestos!C49,'Flujo Base'!S2:S37) -> 148298.17 | D8: =NPV(Supuestos!D49,'Flujo Pesimista'!B2:B37)+NPV(Supuestos!D49,'Flujo Pesimista'!S2:S37) -> 254094.58
A9: Relación B/C | B9: =B7/B8 -> 5.021896 | C9: =C7/C8 -> 2.1741561 | D9: =D7/D8 -> 0.273194 | E9: VP ingresos / VP costos
A10: OPEX mes 36 (£) | B10: ='Flujo Optimista'!S37 -> 2387.2887 | C10: ='Flujo Base'!S37 -> 3164.0913 | D10: ='Flujo Pesimista'!S37 -> 5850.9841
A11: Ingreso mes 36 (£) | B11: ='Flujo Optimista'!T37 -> 24000 | C11: ='Flujo Base'!T37 -> 14400 | D11: ='Flujo Pesimista'!T37 -> 4000

Sheet Precios Azure
A1: Medidor (uksouth, lista minorista) | B1: USD | C1: GBP | D1: Unidad | E1: Fuente
A2: Tipo de cambio implícito GBP/USD | C2: 0.75472 | D2: GBP por USD | E2: Lista GBP de Azure: Service Bus Premium 0,70/0,9275 = APIM Standard v2 0,7237/0,9589
A3: Container Apps consumo — vCPU activa | B3: 3.4e-05 | C3: =B3*$C$2 -> 2.566048e-05 | D3: 1 segundo | E3: https://prices.azure.com/api/retail/prices (consultado 27-10-2026)
A4: Container Apps consumo — memoria activa | B4: 4e-06 | C4: =B4*$C$2 -> 3.01888e-06 | D4: 1 GiB-segundo | E4: https://prices.azure.com/api/retail/prices (consultado 27-10-2026)
A5: Container Registry Basic | B5: 0.1666 | C5: =B5*$C$2 -> 0.12573635 | D5: 1 día | E5: https://prices.azure.com/api/retail/prices (consultado 27-10-2026)
A6: Service Bus Standard — unidad base | B6: 10 | C6: =B6*$C$2 -> 7.5472 | D6: 1 mes | E6: https://prices.azure.com/api/retail/prices (consultado 27-10-2026)
A7: Service Bus Standard — operaciones 13M–100M | B7: 0.8 | C7: =B7*$C$2 -> 0.603776 | D7: 1 millón | E7: https://prices.azure.com/api/retail/prices (consultado 27-10-2026)
A8: Service Bus Premium — unidad de mensajería | B8: 0.9275 | C8: =B8*$C$2 -> 0.7000028 | D8: 1 hora | E8: https://prices.azure.com/api/retail/prices (consultado 27-10-2026)
A9: API Management Standard v2 — unidad | B9: 0.9589 | C9: =B9*$C$2 -> 0.72370101 | D9: 1 hora | E9: https://prices.azure.com/api/retail/prices (consultado 27-10-2026)
A10: Azure OpenAI gpt-4o-mini (global) — entrada | B10: 0.00015 | C10: =B10*$C$2 -> 0.000113208 | D10: 1K tokens | E10: https://prices.azure.com/api/retail/prices (consultado 27-10-2026)
A11: Azure OpenAI gpt-4o-mini (global) — salida | B11: 0.0006 | C11: =B11*$C$2 -> 0.000452832 | D11: 1K tokens | E11: https://prices.azure.com/api/retail/prices (consultado 27-10-2026)
A12: Blob Storage Hot LRS — almacenamiento | B12: 0.0192 | C12: =B12*$C$2 -> 0.014490624 | D12: 1 GB/mes | E12: https://prices.azure.com/api/retail/prices (consultado 27-10-2026)
A13: Blob Storage Hot LRS — escrituras | B13: 0.059 | C13: =B13*$C$2 -> 0.04452848 | D13: 10K ops | E13: https://prices.azure.com/api/retail/prices (consultado 27-10-2026)
A14: Log Analytics — ingesta | B14: 2.88 | C14: =B14*$C$2 -> 2.1735936 | D14: 1 GB | E14: https://prices.azure.com/api/retail/prices (consultado 27-10-2026)

Sheet Flujo Optimista
A1: Mes | B1: CAPEX | C1: Curva adopción | D1: Puestos con módulo | E1: Uso relativo | F1: En operación | G1: Réplicas horario hábil | H1: Réplicas fuera de horario | I1: API inferencia | J1: Jobs batch | K1: Service Bus Std | L1: Service Bus Premium | M1: APIM | N1: Azure OpenAI | O1: Blob (audio + resultados) | P1: Container Registry | Q1: Log Analytics | R1: MLOps | S1: OPEX total | T1: Ingresos (recargo) | U1: Flujo neto | V1: Flujo acumulado
A2: 1 | B2: =IF(A2=1,Supuestos!$B$11,IF(A2=2,Supuestos!$B$12,IF(A2=3,Supuestos!$B$13,0)))*Supuestos!$B$45 -> 17617.893 | C2: =IF(A2<Supuestos!$B$15,0,IF(A2>=Supuestos!$B$16,1,0.1+0.9*(A2-Supuestos!$B$15)/(Supuestos!$B$16-Supuestos!$B$15))) -> 0 | D2: =Supuestos!$B$17*Supuestos!$B$18*C2 -> 0 | E2: =IF(F2=0,0,IF(D2=0,0.05*Supuestos!$B$18,D2/Supuestos!$B$17)) -> 0 | F2: =IF(A2>=Supuestos!$B$14,1,0) -> 0 | G2: =IF(Supuestos!$B$9*Supuestos!$B$20*E2>0,MAX(Supuestos!$B$25,CEILING(Supuestos!$B$9*Supuestos!$B$20*E2/Supuestos!$B$23,1)+Supuestos!$B$24),Supuestos!$B$25) -> 2 | H2: =IF(Supuestos!$B$9*Supuestos!$B$21*E2>0,MAX(Supuestos!$B$25,CEILING(Supuestos!$B$9*Supuestos!$B$21*E2/Supuestos!$B$23,1)+Supuestos!$B$24),Supuestos!$B$25) -> 2 | I2: =F2*Supuestos!$B$40*(G2+H2)*365*Supuestos!$B$48 -> 0 | J2: =F2*Supuestos!$B$40*60*Supuestos!$B$48 -> 0 | K2: =F2*Supuestos!$B$40*IF(Supuestos!$B$37=0,1,0)*('Precios Azure'!$C$6+MAX(0,Supuestos!$B$46*E2*Supuestos!$B$30/1000000-13)*'Precios Azure'!$C$7) -> 0 | L2: =F2*Supuestos!$B$40*Supuestos!$B$37*730*'Precios Azure'!$C$8 -> 0 | M2: =F2*Supuestos!$B$40*Supuestos!$B$38*730*'Precios Azure'!$C$9 -> 0 | N2: =F2*Supuestos!$B$40*Supuestos!$B$46*E2*(Supuestos!$B$31/1000*'Precios Azure'!$C$10+Supuestos!$B$32/1000*'Precios Azure'!$C$11) -> 0 | O2: =F2*Supuestos!$B$40*((Supuestos!$B$46*E2*Supuestos!$B$22*Supuestos!$B$28/1000*Supuestos!$B$29/30.4+Supuestos!$B$46*E2*Supuestos!$B$33/1000000*Supuestos!$B$34)*'Precios Azure'!$C$12+Supuestos!$B$46*E2*Supuestos!$B$35/10000*'Precios Azure'!$C$13) -> 0 | P2: =F2*Supuestos!$B$40*30.4*'Precios Azure'!$C$5 -> 0 | Q2: =F2*Supuestos!$B$40*MAX(0,Supuestos!$B$36-5)*'Precios Azure'!$C$14 -> 0 | R2: =F2*Supuestos!$B$39*Supuestos!$B$44 -> 0 | S2: =SUM(I2:R2) -> 0 | T2: =D2*Supuestos!$B$19*Supuestos!$B$8 -> 0 | U2: =T2-S2-B2 -> -17617.893 | V2: =SUM($U$2:U2) -> -17617.893
A3: 2 | B3: =IF(A3=1,Supuestos!$B$11,IF(A3=2,Supuestos!$B$12,IF(A3=3,Supuestos!$B$13,0)))*Supuestos!$B$45 -> 21652.107 | C3: =IF(A3<Supuestos!$B$15,0,IF(A3>=Supuestos!$B$16,1,0.1+0.9*(A3-Supuestos!$B$15)/(Supuestos!$B$16-Supuestos!$B$15))) -> 0 | D3: =Supuestos!$B$17*Supuestos!$B$18*C3 -> 0 | E3: =IF(F3=0,0,IF(D3=0,0.05*Supuestos!$B$18,D3/Supuestos!$B$17)) -> 0 | F3: =IF(A3>=Supuestos!$B$14,1,0) -> 0 | G3: =IF(Supuestos!$B$9*Supuestos!$B$20*E3>0,MAX(Supuestos!$B$25,CEILING(Supuestos!$B$9*Supuestos!$B$20*E3/Supuestos!$B$23,1)+Supuestos!$B$24),Supuestos!$B$25) -> 2 | H3: =IF(Supuestos!$B$9*Supuestos!$B$21*E3>0,MAX(Supuestos!$B$25,CEILING(Supuestos!$B$9*Supuestos!$B$21*E3/Supuestos!$B$23,1)+Supuestos!$B$24),Supuestos!$B$25) -> 2 | I3: =F3*Supuestos!$B$40*(G3+H3)*365*Supuestos!$B$48 -> 0 | J3: =F3*Supuestos!$B$40*60*Supuestos!$B$48 -> 0 | K3: =F3*Supuestos!$B$40*IF(Supuestos!$B$37=0,1,0)*('Precios Azure'!$C$6+MAX(0,Supuestos!$B$46*E3*Supuestos!$B$30/1000000-13)*'Precios Azure'!$C$7) -> 0 | L3: =F3*Supuestos!$B$40*Supuestos!$B$37*730*'Precios Azure'!$C$8 -> 0 | M3: =F3*Supuestos!$B$40*Supuestos!$B$38*730*'Precios Azure'!$C$9 -> 0 | N3: =F3*Supuestos!$B$40*Supuestos!$B$46*E3*(Supuestos!$B$31/1000*'Precios Azure'!$C$10+Supuestos!$B$32/1000*'Precios Azure'!$C$11) -> 0 | O3: =F3*Supuestos!$B$40*((Supuestos!$B$46*E3*Supuestos!$B$22*Supuestos!$B$28/1000*Supuestos!$B$29/30.4+Supuestos!$B$46*E3*Supuestos!$B$33/1000000*Supuestos!$B$34)*'Precios Azure'!$C$12+Supuestos!$B$46*E3*Supuestos!$B$35/10000*'Precios Azure'!$C$13) -> 0 | P3: =F3*Supuestos!$B$40*30.4*'Precios Azure'!$C$5 -> 0 | Q3: =F3*Supuestos!$B$40*MAX(0,Supuestos!$B$36-5)*'Precios Azure'!$C$14 -> 0 | R3: =F3*Supuestos!$B$39*Supuestos!$B$44 -> 0 | S3: =SUM(I3:R3) -> 0 | T3: =D3*Supuestos!$B$19*Supuestos!$B$8 -> 0 | U3: =T3-S3-B3 -> -21652.107 | V3: =SUM($U$2:U3) -> -39270
A4: 3 | B4: =IF(A4=1,Supuestos!$B$11,IF(A4=2,Supuestos!$B$12,IF(A4=3,Supuestos!$B$13,0)))*Supuestos!$B$45 -> 10596.667 | C4: =IF(A4<Supuestos!$B$15,0,IF(A4>=Supuestos!$B$16,1,0.1+0.9*(A4-Supuestos!$B$15)/(Supuestos!$B$16-Supuestos!$B$15))) -> 0 | D4: =Supuestos!$B$17*Supuestos!$B$18*C4 -> 0 | E4: =IF(F4=0,0,IF(D4=0,0.05*Supuestos!$B$18,D4/Supuestos!$B$17)) -> 0 | F4: =IF(A4>=Supuestos!$B$14,1,0) -> 0 | G4: =IF(Supuestos!$B$9*Supuestos!$B$20*E4>0,MAX(Supuestos!$B$25,CEILING(Supuestos!$B$9*Supuestos!$B$20*E4/Supuestos!$B$23,1)+Supuestos!$B$24),Supuestos!$B$25) -> 2 | H4: =IF(Supuestos!$B$9*Supuestos!$B$21*E4>0,MAX(Supuestos!$B$25,CEILING(Supuestos!$B$9*Supuestos!$B$21*E4/Supuestos!$B$23,1)+Supuestos!$B$24),Supuestos!$B$25) -> 2 | I4: =F4*Supuestos!$B$40*(G4+H4)*365*Supuestos!$B$48 -> 0 | J4: =F4*Supuestos!$B$40*60*Supuestos!$B$48 -> 0 | K4: =F4*Supuestos!$B$40*IF(Supuestos!$B$37=0,1,0)*('Precios Azure'!$C$6+MAX(0,Supuestos!$B$46*E4*Supuestos!$B$30/1000000-13)*'Precios Azure'!$C$7) -> 0 | L4: =F4*Supuestos!$B$40*Supuestos!$B$37*730*'Precios Azure'!$C$8 -> 0 | M4: =F4*Supuestos!$B$40*Supuestos!$B$38*730*'Precios Azure'!$C$9 -> 0 | N4: =F4*Supuestos!$B$40*Supuestos!$B$46*E4*(Supuestos!$B$31/1000*'Precios Azure'!$C$10+Supuestos!$B$32/1000*'Precios Azure'!$C$11) -> 0 | O4: =F4*Supuestos!$B$40*((Supuestos!$B$46*E4*Supuestos!$B$22*Supuestos!$B$28/1000*Supuestos!$B$29/30.4+Supuestos!$B$46*E4*Supuestos!$B$33/1000000*Supuestos!$B$34)*'Precios Azure'!$C$12+Supuestos!$B$46*E4*Supuestos!$B$35/10000*'Precios Azure'!$C$13) -> 0 | P4: =F4*Supuestos!$B$40*30.4*'Precios Azure'!$C$5 -> 0 | Q4: =F4*Supuestos!$B$40*MAX(0,Supuestos!$B$36-5)*'Precios Azure'!$C$14 -> 0 | R4: =F4*Supuestos!$B$39*Supuestos!$B$44 -> 0 | S4: =SUM(I4:R4) -> 0 | T4: =D4*Supuestos!$B$19*Supuestos!$B$8 -> 0 | U4: =T4-S4-B4 -> -10596.667 | V4: =SUM($U$2:U4) -> -49866.667
A5: 4 | B5: =IF(A5=1,Supuestos!$B$11,IF(A5=2,Supuestos!$B$12,IF(A5=3,Supuestos!$B$13,0)))*Supuestos!$B$45 -> 0 | C5: =IF(A5<Supuestos!$B$15,0,IF(A5>=Supuestos!$B$16,1,0.1+0.9*(A5-Supuestos!$B$15)/(Supuestos!$B$16-Supuestos!$B$15))) -> 0.1 | D5: =Supuestos!$B$17*Supuestos!$B$18*C5 -> 150 | E5: =IF(F5=0,0,IF(D5=0,0.05*Supuestos!$B$18,D5/Supuestos!$B$17)) -> 0.075 | F5: =IF(A5>=Supuestos!$B$14,1,0) -> 1 | G5: =IF(Supuestos!$B$9*Supuestos!$B$20*E5>0,MAX(Supuestos!$B$25,CEILING(Supuestos!$B$9*Supuestos!$B$20*E5/Supuestos!$B$23,1)+Supuestos!$B$24),Supuestos!$B$25) -> 2 | H5: =IF(Supuestos!$B$9*Supuestos!$B$21*E5>0,MAX(Supuestos!$B$25,CEILING(Supuestos!$B$9*Supuestos!$B$21*E5/Supuestos!$B$23,1)+Supuestos!$B$24),Supuestos!$B$25) -> 2 | I5: =F5*Supuestos!$B$40*(G5+H5)*365*Supuestos!$B$48 -> 141.61506 | J5: =F5*Supuestos!$B$40*60*Supuestos!$B$48 -> 5.8197969 | K5: =F5*Supuestos!$B$40*IF(Supuestos!$B$37=0,1,0)*('Precios Azure'!$C$6+MAX(0,Supuestos!$B$46*E5*Supuestos!$B$30/1000000-13)*'Precios Azure'!$C$7) -> 0 | L5: =F5*Supuestos!$B$40*Supuestos!$B$37*730*'Precios Azure'!$C$8 -> 434.35174 | M5: =F5*Supuestos!$B$40*Supuestos!$B$38*730*'Precios Azure'!$C$9 -> 449.05648 | N5: =F5*Supuestos!$B$40*Supuestos!$B$46*E5*(Supuestos!$B$31/1000*'Precios Azure'!$C$10+Supuestos!$B$32/1000*'Precios Azure'!$C$11) -> 18.513744 | O5: =F5*Supuestos!$B$40*((Supuestos!$B$46*E5*Supuestos!$B$22*Supuestos!$B$28/1000*Supuestos!$B$29/30.4+Supuestos!$B$46*E5*Supuestos!$B$33/1000000*Supuestos!$B$34)*'Precios Azure'!$C$12+Supuestos!$B$46*E5*Supuestos!$B$35/10000*'Precios Azure'!$C$13) -> 11.023235 | P5: =F5*Supuestos!$B$40*30.4*'Precios Azure'!$C$5 -> 3.2490273 | Q5: =F5*Supuestos!$B$40*MAX(0,Supuestos!$B$36-5)*'Precios Azure'!$C$14 -> 101.6155 | R5: =F5*Supuestos!$B$39*Supuestos!$B$44 -> 850 | S5: =SUM(I5:R5) -> 2015.2446 | T5: =D5*Supuestos!$B$19*Supuestos!$B$8 -> 2400 | U5: =T5-S5-B5 -> 384.75543 | V5: =SUM($U$2:U5) -> -49481.911
A6: 5 | B6: =IF(A6=1,Supuestos!$B$11,IF(A6=2,Supuestos!$B$12,IF(A6=3,Supuestos!$B$13,0)))*Supuestos!$B$45 -> 0 | C6: =IF(A6<Supuestos!$B$15,0,IF(A6>=Supuestos!$B$16,1,0.1+0.9*(A6-Supuestos!$B$15)/(Supuestos!$B$16-Supuestos!$B$15))) -> 0.2125 | D6: =Supuestos!$B$17*Supuestos!$B$18*C6 -> 318.75 | E6: =IF(F6=0,0,IF(D6=0,0.05*Supuestos!$B$18,D6/Supuestos!$B$17)) -> 0.159375 | F6: =IF(A6>=Supuestos!$B$14,1,0) -> 1 | G6: =IF(Supuestos!$B$9*Supuestos!$B$20*E6>0,MAX(Supuestos!$B$25,CEILING(Supuestos!$B$9*Supuestos!$B$20*E6/Supuestos!$B$23,1)+Supuestos!$B$24),Supuestos!$B$25) -> 2 | H6: =IF(Supuestos!$B$9*Supuestos!$B$21*E6>0,MAX(Supuestos!$B$25,CEILING(Supuestos!$B$9*Supuestos!$B$21*E6/Supuestos!$B$23,1)+Supuestos!$B$24),Supuestos!$B$25) -> 2 | I6: =F6*Supuestos!$B$40*(G6+H6)*365*Supuestos!$B$48 -> 141.61506 | J6: =F6*Supuestos!$B$40*60*Supuestos!$B$48 -> 5.8197969 | K6: =F6*Supuestos!$B$40*IF(Supuestos!$B$37=0,1,0)*('Precios Azure'!$C$6+MAX(0,Supuestos!$B$46*E6*Supuestos!$B$30/1000000-13)*'Precios Azure'!$C$7) -> 0 | L6: =F6*Supuestos!$B$40*Supuestos!$B$37*730*'Precios Azure'!$C$8 -> 434.35174 | M6: =F6*Supuestos!$B$40*Supuestos!$B$38*730*'Precios Azure'!$C$9 -> 449.05648 | N6: =F6*Supuestos!$B$40*Supuestos!$B$46*E6*(Supuestos!$B$31/1000*'Precios Azure'!$C$10+Supuestos!$B$32/1000*'Precios Azure'!$C$11) -> 39.341706 | O6: =F6*Supuestos!$B$40*((Supuestos!$B$46*E6*Supuestos!$B$22*Supuestos!$B$28/1000*Supuestos!$B$29/30.4+Supuestos!$B$46*E6*Supuestos!$B$33/1000000*Supuestos!$B$34)*'Precios Azure'!$C$12+Supuestos!$B$46*E6*Supuestos!$B$35/10000*'Precios Azure'!$C$13) -> 23.424374 | P6: =F6*Supuestos!$B$40*30.4*'Precios Azure'!$C$5 -> 3.2490273 | Q6: =F6*Supuestos!$B$40*MAX(0,Supuestos!$B$36-5)*'Precios Azure'!$C$14 -> 101.6155 | R6: =F6*Supuestos!$B$39*Supuestos!$B$44 -> 850 | S6: =SUM(I6:R6) -> 2048.4737 | T6: =D6*Supuestos!$B$19*Supuestos!$B$8 -> 5100 | U6: =T6-S6-B6 -> 3051.5263 | V6: =SUM($U$2:U6) -> -46430.385
A7: 6 | B7: =IF(A7=1,Supuestos!$B$11,IF(A7=2,Supuestos!$B$12,IF(A7=3,Supuestos!$B$13,0)))*Supuestos!$B$45 -> 0 | C7: =IF(A7<Supuestos!$B$15,0,IF(A7>=Supuestos!$B$16,1,0.1+0.9*(A7-Supuestos!$B$15)/(Supuestos!$B$16-Supuestos!$B$15))) -> 0.325 | D7: =Supuestos!$B$17*Supuestos!$B$18*C7 -> 487.5 | E7: =IF(F7=0,0,IF(D7=0,0.05*Supuestos!$B$18,D7/Supuestos!$B$17)) -> 0.24375 | F7: =IF(A7>=Supuestos!$B$14,1,0) -> 1 | G7: =IF(Supuestos!$B$9*Supuestos!$B$20*E7>0,MAX(Supuestos!$B$25,CEILING(Supuestos!$B$9*Supuestos!$B$20*E7/Supuestos!$B$23,1)+Supuestos!$B$24),Supuestos!$B$25) -> 3 | H7: =IF(Supuestos!$B$9*Supuestos!$B$21*E7>0,MAX(Supuestos!$B$25,CEILING(Supuestos!$B$9*Supuestos!$B$21*E7/Supuestos!$B$23,1)+Supuestos!$B$24),Supuestos!$B$25) -> 2 | I7: =F7*Supuestos!$B$40*(G7+H7)*365*Supuestos!$B$48 -> 177.01882 | J7: =F7*Supuestos!$B$40*60*Supuestos!$B$48 -> 5.8197969 | K7: =F7*Supuestos!$B$40*IF(Supuestos!$B$37=0,1,0)*('Precios Azure'!$C$6+MAX(0,Supuestos!$B$46*E7*Supuestos!$B$30/1000000-13)*'Precios Azure'!$C$7) -> 0 | L7: =F7*Supuestos!$B$40*Supuestos!$B$37*730*'Precios Azure'!$C$8 -> 434.35174 | M7: =F7*Supuestos!$B$40*Supuestos!$B$38*730*'Precios Azure'!$C$9 -> 449.05648 | N7: =F7*Supuestos!$B$40*Supuestos!$B$46*E7*(Supuestos!$B$31/1000*'Precios Azure'!$C$10+Supuestos!$B$32/1000*'Precios Azure'!$C$11) -> 60.169668 | O7: =F7*Supuestos!$B$40*((Supuestos!$B$46*E7*Supuestos!$B$22*Supuestos!$B$28/1000*Supuestos!$B$29/30.4+Supuestos!$B$46*E7*Supuestos!$B$33/1000000*Supuestos!$B$34)*'Precios Azure'!$C$12+Supuestos!$B$46*E7*Supuestos!$B$35/10000*'Precios Azure'!$C$13) -> 35.825513 | P7: =F7*Supuestos!$B$40*30.4*'Precios Azure'!$C$5 -> 3.2490273 | Q7: =F7*Supuestos!$B$40*MAX(0,Supuestos!$B$36-5)*'Precios Azure'!$C$14 -> 101.6155 | R7: =F7*Supuestos!$B$39*Supuestos!$B$44 -> 850 | S7: =SUM(I7:R7) -> 2117.1065 | T7: =D7*Supuestos!$B$19*Supuestos!$B$8 -> 7800 | U7: =T7-S7-B7 -> 5682.8935 | V7: =SUM($U$2:U7) -> -40747.491
A8: 7 | B8: =IF(A8=1,Supuestos!$B$11,IF(A8=2,Supuestos!$B$12,IF(A8=3,Supuestos!$B$13,0)))*Supuestos!$B$45 -> 0 | C8: =IF(A8<Supuestos!$B$15,0,IF(A8>=Supuestos!$B$16,1,0.1+0.9*(A8-Supuestos!$B$15)/(Supuestos!$B$16-Supuestos!$B$15))) -> 0.4375 | D8: =Supuestos!$B$17*Supuestos!$B$18*C8 -> 656.25 | E8: =IF(F8=0,0,IF(D8=0,0.05*Supuestos!$B$18,D8/Supuestos!$B$17)) -> 0.328125 | F8: =IF(A8>=Supuestos!$B$14,1,0) -> 1 | G8: =IF(Supuestos!$B$9*Supuestos!$B$20*E8>0,MAX(Supuestos!$B$25,CEILING(Supuestos!$B$9*Supuestos!$B$20*E8/Supuestos!$B$23,1)+Supuestos!$B$24),Supuestos!$B$25) -> 3 | H8: =IF(Supuestos!$B$9*Supuestos!$B$21*E8>0,MAX(Supuestos!$B$25,CEILING(Supuestos!$B$9*Supuestos!$B$21*E8/Supuestos!$B$23,1)+Supuestos!$B$24),Supuestos!$B$25) -> 2 | I8: =F8*Supuestos!$B$40*(G8+H8)*365*Supuestos!$B$48 -> 177.01882 | J8: =F8*Supuestos!$B$40*60*Supuestos!$B$48 -> 5.8197969 | K8: =F8*Supuestos!$B$40*IF(Supuestos!$B$37=0,1,0)*('Precios Azure'!$C$6+MAX(0,Supuestos!$B$46*E8*Supuestos!$B$30/1000000-13)*'Precios Azure'!$C$7) -> 0 | L8: =F8*Supuestos!$B$40*Supuestos!$B$37*730*'Precios Azure'!$C$8 -> 434.35174 | M8: =F8*Supuestos!$B$40*Supuestos!$B$38*730*'Precios Azure'!$C$9 -> 449.05648 | N8: =F8*Supuestos!$B$40*Supuestos!$B$46*E8*(Supuestos!$B$31/1000*'Precios Azure'!$C$10+Supuestos!$B$32/1000*'Precios Azure'!$C$11) -> 80.99763 | O8: =F8*Supuestos!$B$40*((Supuestos!$B$46*E8*Supuestos!$B$22*Supuestos!$B$28/1000*Supuestos!$B$29/30.4+Supuestos!$B$46*E8*Supuestos!$B$33/1000000*Supuestos!$B$34)*'Precios Azure'!$C$12+Supuestos!$B$46*E8*Supuestos!$B$35/10000*'Precios Azure'!$C$13) -> 48.226652 | P8: =F8*Supuestos!$B$40*30.4*'Precios Azure'!$C$5 -> 3.2490273 | Q8: =F8*Supuestos!$B$40*MAX(0,Supuestos!$B$36-5)*'Precios Azure'!$C$14 -> 101.6155 | R8: =F8*Supuestos!$B$39*Supuestos!$B$44 -> 850 | S8: =SUM(I8:R8) -> 2150.3356 | T8: =D8*Supuestos!$B$19*Supuestos!$B$8 -> 10500 | U8: =T8-S8-B8 -> 8349.6644 | V8: =SUM($U$2:U8) -> -32397.827
A9: 8 | B9: =IF(A9=1,Supuestos!$B$11,IF(A9=2,Supuestos!$B$12,IF(A9=3,Supuestos!$B$13,0)))*Supuestos!$B$45 -> 0 | C9: =IF(A9<Supuestos!$B$15,0,IF(A9>=Supuestos!$B$16,1,0.1+0.9*(A9-Supuestos!$B$15)/(Supuestos!$B$16-Supuestos!$B$15))) -> 0.55 | D9: =Supuestos!$B$17*Supuestos!$B$18*C9 -> 825 | E9: =IF(F9=0,0,IF(D9=0,0.05*Supuestos!$B$18,D9/Supuestos!$B$17)) -> 0.4125 | F9: =IF(A9>=Supuestos!$B$14,1,0) -> 1 | G9: =IF(Supuestos!$B$9*Supuestos!$B$20*E9>0,MAX(Supuestos!$B$25,CEILING(Supuestos!$B$9*Supuestos!$B$20*E9/Supuestos!$B$23,1)+Supuestos!$B$24),Supuestos!$B$25) -> 3 | H9: =IF(Supuestos!$B$9*Supuestos!$B$21*E9>0,MAX(Supuestos!$B$25,CEILING(Supuestos!$B$9*Supuestos!$B$21*E9/Supuestos!$B$23,1)+Supuestos!$B$24),Supuestos!$B$25) -> 2 | I9: =F9*Supuestos!$B$40*(G9+H9)*365*Supuestos!$B$48 -> 177.01882 | J9: =F9*Supuestos!$B$40*60*Supuestos!$B$48 -> 5.8197969 | K9: =F9*Supuestos!$B$40*IF(Supuestos!$B$37=0,1,0)*('Precios Azure'!$C$6+MAX(0,Supuestos!$B$46*E9*Supuestos!$B$30/1000000-13)*'Precios Azure'!$C$7) -> 0 | L9: =F9*Supuestos!$B$40*Supuestos!$B$37*730*'Precios Azure'!$C$8 -> 434.35174 | M9: =F9*Supuestos!$B$40*Supuestos!$B$38*730*'Precios Azure'!$C$9 -> 449.05648 | N9: =F9*Supuestos!$B$40*Supuestos!$B$46*E9*(Supuestos!$B$31/1000*'Precios Azure'!$C$10+Supuestos!$B$32/1000*'Precios Azure'!$C$11) -> 101.82559 | O9: =F9*Supuestos!$B$40*((Supuestos!$B$46*E9*Supuestos!$B$22*Supuestos!$B$28/1000*Supuestos!$B$29/30.4+Supuestos!$B$46*E9*Supuestos!$B$33/1000000*Supuestos!$B$34)*'Precios Azure'!$C$12+Supuestos!$B$46*E9*Supuestos!$B$35/10000*'Precios Azure'!$C$13) -> 60.627791 | P9: =F9*Supuestos!$B$40*30.4*'Precios Azure'!$C$5 -> 3.2490273 | Q9: =F9*Supuestos!$B$40*MAX(0,Supuestos!$B$36-5)*'Precios Azure'!$C$14 -> 101.6155 | R9: =F9*Supuestos!$B$39*Supuestos!$B$44 -> 850 | S9: =SUM(I9:R9) -> 2183.5647 | T9: =D9*Supuestos!$B$19*Supuestos!$B$8 -> 13200 | U9: =T9-S9-B9 -> 11016.435 | V9: =SUM($U$2:U9) -> -21381.392
A10: 9 | B10: =IF(A10=1,Supuestos!$B$11,IF(A10=2,Supuestos!$B$12,IF(A10=3,Supuestos!$B$13,0)))*Supuestos!$B$45 -> 0 | C10: =IF(A10<Supuestos!$B$15,0,IF(A10>=Supuestos!$B$16,1,0.1+0.9*(A10-Supuestos!$B$15)/(Supuestos!$B$16-Supuestos!$B$15))) -> 0.6625 | D10: =Supuestos!$B$17*Supuestos!$B$18*C10 -> 993.75 | E10: =IF(F10=0,0,IF(D10=0,0.05*Supuestos!$B$18,D10/Supuestos!$B$17)) -> 0.496875 | F10: =IF(A10>=Supuestos!$B$14,1,0) -> 1 | G10: =IF(Supuestos!$B$9*Supuestos!$B$20*E10>0,MAX(Supuestos!$B$25,CEILING(Supuestos!$B$9*Supuestos!$B$20*E10/Supuestos!$B$23,1)+Supuestos!$B$24),Supuestos!$B$25) -> 4 | H10: =IF(Supuestos!$B$9*Supuestos!$B$21*E10>0,MAX(Supuestos!$B$25,CEILING(Supuestos!$B$9*Supuestos!$B$21*E10/Supuestos!$B$23,1)+Supuestos!$B$24),Supuestos!$B$25) -> 2 | I10: =F10*Supuestos!$B$40*(G10+H10)*365*Supuestos!$B$48 -> 212.42259 | J10: =F10*Supuestos!$B$40*60*Supuestos!$B$48 -> 5.8197969 | K10: =F10*Supuestos!$B$40*IF(Supuestos!$B$37=0,1,0)*('Precios Azure'!$C$6+MAX(0,Supuestos!$B$46*E10*Supuestos!$B$30/1000000-13)*'Precios Azure'!$C$7) -> 0 | L10: =F10*Supuestos!$B$40*Supuestos!$B$37*730*'Precios Azure'!$C$8 -> 434.35174 | M10: =F10*Supuestos!$B$40*Supuestos!$B$38*730*'Precios Azure'!$C$9 -> 449.05648 | N10: =F10*Supuestos!$B$40*Supuestos!$B$46*E10*(Supuestos!$B$31/1000*'Precios Azure'!$C$10+Supuestos!$B$32/1000*'Precios Azure'!$C$11) -> 122.65355 | O10: =F10*Supuestos!$B$40*((Supuestos!$B$46*E10*Supuestos!$B$22*Supuestos!$B$28/1000*Supuestos!$B$29/30.4+Supuestos!$B$46*E10*Supuestos!$B$33/1000000*Supuestos!$B$34)*'Precios Azure'!$C$12+Supuestos!$B$46*E10*Supuestos!$B$35/10000*'Precios Azure'!$C$13) -> 73.028931 | P10: =F10*Supuestos!$B$40*30.4*'Precios Azure'!$C$5 -> 3.2490273 | Q10: =F10*Supuestos!$B$40*MAX(0,Supuestos!$B$36-5)*'Precios Azure'!$C$14 -> 101.6155 | R10: =F10*Supuestos!$B$39*Supuestos!$B$44 -> 850 | S10: =SUM(I10:R10) -> 2252.1976 | T10: =D10*Supuestos!$B$19*Supuestos!$B$8 -> 15900 | U10: =T10-S10-B10 -> 13647.802 | V10: =SUM($U$2:U10) -> -7733.5894
A11: 10 | B11: =IF(A11=1,Supuestos!$B$11,IF(A11=2,Supuestos!$B$12,IF(A11=3,Supuestos!$B$13,0)))*Supuestos!$B$45 -> 0 | C11: =IF(A11<Supuestos!$B$15,0,IF(A11>=Supuestos!$B$16,1,0.1+0.9*(A11-Supuestos!$B$15)/(Supuestos!$B$16-Supuestos!$B$15))) -> 0.775 | D11: =Supuestos!$B$17*Supuestos!$B$18*C11 -> 1162.5 | E11: =IF(F11=0,0,IF(D11=0,0.05*Supuestos!$B$18,D11/Supuestos!$B$17)) -> 0.58125 | F11: =IF(A11>=Supuestos!$B$14,1,0) -> 1 | G11: =IF(Supuestos!$B$9*Supuestos!$B$20*E11>0,MAX(Supuestos!$B$25,CEILING(Supuestos!$B$9*Supuestos!$B$20*E11/Supuestos!$B$23,1)+Supuestos!$B$24),Supuestos!$B$25) -> 4 | H11: =IF(Supuestos!$B$9*Supuestos!$B$21*E11>0,MAX(Supuestos!$B$25,CEILING(Supuestos!$B$9*Supuestos!$B$21*E11/Supuestos!$B$23,1)+Supuestos!$B$24),Supuestos!$B$25) -> 2 | I11: =F11*Supuestos!$B$40*(G11+H11)*365*Supuestos!$B$48 -> 212.42259 | J11: =F11*Supuestos!$B$40*60*Supuestos!$B$48 -> 5.8197969 | K11: =F11*Supuestos!$B$40*IF(Supuestos!$B$37=0,1,0)*('Precios Azure'!$C$6+MAX(0,Supuestos!$B$46*E11*Supuestos!$B$30/1000000-13)*'Precios Azure'!$C$7) -> 0 | L11: =F11*Supuestos!$B$40*Supuestos!$B$37*730*'Precios Azure'!$C$8 -> 434.35174 | M11: =F11*Supuestos!$B$40*Supuestos!$B$38*730*'Precios Azure'!$C$9 -> 449.05648 | N11: =F11*Supuestos!$B$40*Supuestos!$B$46*E11*(Supuestos!$B$31/1000*'Precios Azure'!$C$10+Supuestos!$B$32/1000*'Precios Azure'!$C$11) -> 143.48152 | O11: =F11*Supuestos!$B$40*((Supuestos!$B$46*E11*Supuestos!$B$22*Supuestos!$B$28/1000*Supuestos!$B$29/30.4+Supuestos!$B$46*E11*Supuestos!$B$33/1000000*Supuestos!$B$34)*'Precios Azure'!$C$12+Supuestos!$B$46*E11*Supuestos!$B$35/10000*'Precios Azure'!$C$13) -> 85.43007 | P11: =F11*Supuestos!$B$40*30.4*'Precios Azure'!$C$5 -> 3.2490273 | Q11: =F11*Supuestos!$B$40*MAX(0,Supuestos!$B$36-5)*'Precios Azure'!$C$14 -> 101.6155 | R11: =F11*Supuestos!$B$39*Supuestos!$B$44 -> 850 | S11: =SUM(I11:R11) -> 2285.4267 | T11: =D11*Supuestos!$B$19*Supuestos!$B$8 -> 18600 | U11: =T11-S11-B11 -> 16314.573 | V11: =SUM($U$2:U11) -> 8580.9838
A12: 11 | B12: =IF(A12=1,Supuestos!$B$11,IF(A12=2,Supuestos!$B$12,IF(A12=3,Supuestos!$B$13,0)))*Supuestos!$B$45 -> 0 | C12: =IF(A12<Supuestos!$B$15,0,IF(A12>=Supuestos!$B$16,1,0.1+0.9*(A12-Supuestos!$B$15)/(Supuestos!$B$16-Supuestos!$B$15))) -> 0.8875 | D12: =Supuestos!$B$17*Supuestos!$B$18*C12 -> 1331.25 | E12: =IF(F12=0,0,IF(D12=0,0.05*Supuestos!$B$18,D12/Supuestos!$B$17)) -> 0.665625 | F12: =IF(A12>=Supuestos!$B$14,1,0) -> 1 | G12: =IF(Supuestos!$B$9*Supuestos!$B$20*E12>0,MAX(Supuestos!$B$25,CEILING(Supuestos!$B$9*Supuestos!$B$20*E12/Supuestos!$B$23,1)+Supuestos!$B$24),Supuestos!$B$25) -> 4 | H12: =IF(Supuestos!$B$9*Supuestos!$B$21*E12>0,MAX(Supuestos!$B$25,CEILING(Supuestos!$B$9*Supuestos!$B$21*E12/Supuestos!$B$23,1)+Supuestos!$B$24),Supuestos!$B$25) -> 2 | I12: =F12*Supuestos!$B$40*(G12+H12)*365*Supuestos!$B$48 -> 212.42259 | J12: =F12*Supuestos!$B$40*60*Supuestos!$B$48 -> 5.8197969 | K12: =F12*Supuestos!$B$40*IF(Supuestos!$B$37=0,1,0)*('Precios Azure'!$C$6+MAX(0,Supuestos!$B$46*E12*Supuestos!$B$30/1000000-13)*'Precios Azure'!$C$7) -> 0 | L12: =F12*Supuestos!$B$40*Supuestos!$B$37*730*'Precios Azure'!$C$8 -> 434.35174 | M12: =F12*Supuestos!$B$40*Supuestos!$B$38*730*'Precios Azure'!$C$9 -> 449.05648 | N12: =F12*Supuestos!$B$40*Supuestos!$B$46*E12*(Supuestos!$B$31/1000*'Precios Azure'!$C$10+Supuestos!$B$32/1000*'Precios Azure'!$C$11) -> 164.30948 | O12: =F12*Supuestos!$B$40*((Supuestos!$B$46*E12*Supuestos!$B$22*Supuestos!$B$28/1000*Supuestos!$B$29/30.4+Supuestos!$B$46*E12*Supuestos!$B$33/1000000*Supuestos!$B$34)*'Precios Azure'!$C$12+Supuestos!$B$46*E12*Supuestos!$B$35/10000*'Precios Azure'!$C$13) -> 97.831209 | P12: =F12*Supuestos!$B$40*30.4*'Precios Azure'!$C$5 -> 3.2490273 | Q12: =F12*Supuestos!$B$40*MAX(0,Supuestos!$B$36-5)*'Precios Azure'!$C$14 -> 101.6155 | R12: =F12*Supuestos!$B$39*Supuestos!$B$44 -> 850 | S12: =SUM(I12:R12) -> 2318.6558 | T12: =D12*Supuestos!$B$19*Supuestos!$B$8 -> 21300 | U12: =T12-S12-B12 -> 18981.344 | V12: =SUM($U$2:U12) -> 27562.328
A13: 12 | B13: =IF(A13=1,Supuestos!$B$11,IF(A13=2,Supuestos!$B$12,IF(A13=3,Supuestos!$B$13,0)))*Supuestos!$B$45 -> 0 | C13: =IF(A13<Supuestos!$B$15,0,IF(A13>=Supuestos!$B$16,1,0.1+0.9*(A13-Supuestos!$B$15)/(Supuestos!$B$16-Supuestos!$B$15))) -> 1 | D13: =Supuestos!$B$17*Supuestos!$B$18*C13 -> 1500 | E13: =IF(F13=0,0,IF(D13=0,0.05*Supuestos!$B$18,D13/Supuestos!$B$17)) -> 0.75 | F13: =IF(A13>=Supuestos!$B$14,1,0) -> 1 | G13: =IF(Supuestos!$B$9*Supuestos!$B$20*E13>0,MAX(Supuestos!$B$25,CEILING(Supuestos!$B$9*Supuestos!$B$20*E13/Supuestos!$B$23,1)+Supuestos!$B$24),Supuestos!$B$25) -> 5 | H13: =IF(Supuestos!$B$9*Supuestos!$B$21*E13>0,MAX(Supuestos!$B$25,CEILING(Supuestos!$B$9*Supuestos!$B$21*E13/Supuestos!$B$23,1)+Supuestos!$B$24),Supuestos!$B$25) -> 2 | I13: =F13*Supuestos!$B$40*(G13+H13)*365*Supuestos!$B$48 -> 247.82635 | J13: =F13*Supuestos!$B$40*60*Supuestos!$B$48 -> 5.8197969 | K13: =F13*Supuestos!$B$40*IF(Supuestos!$B$37=0,1,0)*('Precios Azure'!$C$6+MAX(0,Supuestos!$B$46*E13*Supuestos!$B$30/1000000-13)*'Precios Azure'!$C$7) -> 0 | L13: =F13*Supuestos!$B$40*Supuestos!$B$37*730*'Precios Azure'!$C$8 -> 434.35174 | M13: =F13*Supuestos!$B$40*Supuestos!$B$38*730*'Precios Azure'!$C$9 -> 449.05648 | N13: =F13*Supuestos!$B$40*Supuestos!$B$46*E13*(Supuestos!$B$31/1000*'Precios Azure'!$C$10+Supuestos!$B$32/1000*'Precios Azure'!$C$11) -> 185.13744 | O13: =F13*Supuestos!$B$40*((Supuestos!$B$46*E13*Supuestos!$B$22*Supuestos!$B$28/1000*Supuestos!$B$29/30.4+Supuestos!$B$46*E13*Supuestos!$B$33/1000000*Supuestos!$B$34)*'Precios Azure'!$C$12+Supuestos!$B$46*E13*Supuestos!$B$35/10000*'Precios Azure'!$C$13) -> 110.23235 | P13: =F13*Supuestos!$B$40*30.4*'Precios Azure'!$C$5 -> 3.2490273 | Q13: =F13*Supuestos!$B$40*MAX(0,Supuestos!$B$36-5)*'Precios Azure'!$C$14 -> 101.6155 | R13: =F13*Supuestos!$B$39*Supuestos!$B$44 -> 850 | S13: =SUM(I13:R13) -> 2387.2887 | T13: =D13*Supuestos!$B$19*Supuestos!$B$8 -> 24000 | U13: =T13-S13-B13 -> 21612.711 | V13: =SUM($U$2:U13) -> 49175.039
... A37: 36 | B37: =IF(A37=1,Supuestos!$B$11,IF(A37=2,Supuestos!$B$12,IF(A37=3,Supuestos!$B$13,0)))*Supuestos!$B$45 -> 0 | C37: =IF(A37<Supuestos!$B$15,0,IF(A37>=Supuestos!$B$16,1,0.1+0.9*(A37-Supuestos!$B$15)/(Supuestos!$B$16-Supuestos!$B$15))) -> 1 | D37: =Supuestos!$B$17*Supuestos!$B$18*C37 -> 1500 | E37: =IF(F37=0,0,IF(D37=0,0.05*Supuestos!$B$18,D37/Supuestos!$B$17)) -> 0.75 | F37: =IF(A37>=Supuestos!$B$14,1,0) -> 1 | G37: =IF(Supuestos!$B$9*Supuestos!$B$20*E37>0,MAX(Supuestos!$B$25,CEILING(Supuestos!$B$9*Supuestos!$B$20*E37/Supuestos!$B$23,1)+Supuestos!$B$24),Supuestos!$B$25) -> 5 | H37: =IF(Supuestos!$B$9*Supuestos!$B$21*E37>0,MAX(Supuestos!$B$25,CEILING(Supuestos!$B$9*Supuestos!$B$21*E37/Supuestos!$B$23,1)+Supuestos!$B$24),Supuestos!$B$25) -> 2 | I37: =F37*Supuestos!$B$40*(G37+H37)*365*Supuestos!$B$48 -> 247.82635 | J37: =F37*Supuestos!$B$40*60*Supuestos!$B$48 -> 5.8197969 | K37: =F37*Supuestos!$B$40*IF(Supuestos!$B$37=0,1,0)*('Precios Azure'!$C$6+MAX(0,Supuestos!$B$46*E37*Supuestos!$B$30/1000000-13)*'Precios Azure'!$C$7) -> 0 | L37: =F37*Supuestos!$B$40*Supuestos!$B$37*730*'Precios Azure'!$C$8 -> 434.35174 | M37: =F37*Supuestos!$B$40*Supuestos!$B$38*730*'Precios Azure'!$C$9 -> 449.05648 | N37: =F37*Supuestos!$B$40*Supuestos!$B$46*E37*(Supuestos!$B$31/1000*'Precios Azure'!$C$10+Supuestos!$B$32/1000*'Precios Azure'!$C$11) -> 185.13744 | O37: =F37*Supuestos!$B$40*((Supuestos!$B$46*E37*Supuestos!$B$22*Supuestos!$B$28/1000*Supuestos!$B$29/30.4+Supuestos!$B$46*E37*Supuestos!$B$33/1000000*Supuestos!$B$34)*'Precios Azure'!$C$12+Supuestos!$B$46*E37*Supuestos!$B$35/10000*'Precios Azure'!$C$13) -> 110.23235 | P37: =F37*Supuestos!$B$40*30.4*'Precios Azure'!$C$5 -> 3.2490273 | Q37: =F37*Supuestos!$B$40*MAX(0,Supuestos!$B$36-5)*'Precios Azure'!$C$14 -> 101.6155 | R37: =F37*Supuestos!$B$39*Supuestos!$B$44 -> 850 | S37: =SUM(I37:R37) -> 2387.2887 | T37: =D37*Supuestos!$B$19*Supuestos!$B$8 -> 24000 | U37: =T37-S37-B37 -> 21612.711 | V37: =SUM($U$2:U37) -> 567880.11

Sheet Flujo Base
A1: Mes | B1: CAPEX | C1: Curva adopción | D1: Puestos con módulo | E1: Uso relativo | F1: En operación | G1: Réplicas horario hábil | H1: Réplicas fuera de horario | I1: API inferencia | J1: Jobs batch | K1: Service Bus Std | L1: Service Bus Premium | M1: APIM | N1: Azure OpenAI | O1: Blob (audio + resultados) | P1: Container Registry | Q1: Log Analytics | R1: MLOps | S1: OPEX total | T1: Ingresos (recargo) | U1: Flujo neto | V1: Flujo acumulado
A2: 1 | B2: =IF(A2=1,Supuestos!$C$11,IF(A2=2,Supuestos!$C$12,IF(A2=3,Supuestos!$C$13,0)))*Supuestos!$C$45 -> 22799.627 | C2: =IF(A2<Supuestos!$C$15,0,IF(A2>=Supuestos!$C$16,1,0.1+0.9*(A2-Supuestos!$C$15)/(Supuestos!$C$16-Supuestos!$C$15))) -> 0 | D2: =Supuestos!$C$17*Supuestos!$C$18*C2 -> 0 | E2: =IF(F2=0,0,IF(D2=0,0.05*Supuestos!$C$18,D2/Supuestos!$C$17)) -> 0 | F2: =IF(A2>=Supuestos!$C$14,1,0) -> 0 | G2: =IF(Supuestos!$C$9*Supuestos!$C$20*E2>0,MAX(Supuestos!$C$25,CEILING(Supuestos!$C$9*Supuestos!$C$20*E2/Supuestos!$C$23,1)+Supuestos!$C$24),Supuestos!$C$25) -> 2 | H2: =IF(Supuestos!$C$9*Supuestos!$C$21*E2>0,MAX(Supuestos!$C$25,CEILING(Supuestos!$C$9*Supuestos!$C$21*E2/Supuestos!$C$23,1)+Supuestos!$C$24),Supuestos!$C$25) -> 2 | I2: =F2*Supuestos!$C$40*(G2+H2)*365*Supuestos!$C$48 -> 0 | J2: =F2*Supuestos!$C$40*60*Supuestos!$C$48 -> 0 | K2: =F2*Supuestos!$C$40*IF(Supuestos!$C$37=0,1,0)*('Precios Azure'!$C$6+MAX(0,Supuestos!$C$46*E2*Supuestos!$C$30/1000000-13)*'Precios Azure'!$C$7) -> 0 | L2: =F2*Supuestos!$C$40*Supuestos!$C$37*730*'Precios Azure'!$C$8 -> 0 | M2: =F2*Supuestos!$C$40*Supuestos!$C$38*730*'Precios Azure'!$C$9 -> 0 | N2: =F2*Supuestos!$C$40*Supuestos!$C$46*E2*(Supuestos!$C$31/1000*'Precios Azure'!$C$10+Supuestos!$C$32/1000*'Precios Azure'!$C$11) -> 0 | O2: =F2*Supuestos!$C$40*((Supuestos!$C$46*E2*Supuestos!$C$22*Supuestos!$C$28/1000*Supuestos!$C$29/30.4+Supuestos!$C$46*E2*Supuestos!$C$33/1000000*Supuestos!$C$34)*'Precios Azure'!$C$12+Supuestos!$C$46*E2*Supuestos!$C$35/10000*'Precios Azure'!$C$13) -> 0 | P2: =F2*Supuestos!$C$40*30.4*'Precios Azure'!$C$5 -> 0 | Q2: =F2*Supuestos!$C$40*MAX(0,Supuestos!$C$36-5)*'Precios Azure'!$C$14 -> 0 | R2: =F2*Supuestos!$C$39*Supuestos!$C$44 -> 0 | S2: =SUM(I2:R2) -> 0 | T2: =D2*Supuestos!$C$19*Supuestos!$C$8 -> 0 | U2: =T2-S2-B2 -> -22799.627 | V2: =SUM($U$2:U2) -> -22799.627
A3: 2 | B3: =IF(A3=1,Supuestos!$C$11,IF(A3=2,Supuestos!$C$12,IF(A3=3,Supuestos!$C$13,0)))*Supuestos!$C$45 -> 28020.373 | C3: =IF(A3<Supuestos!$C$15,0,IF(A3>=Supuestos!$C$16,1,0.1+0.9*(A3-Supuestos!$C$15)/(Supuestos!$C$16-Supuestos!$C$15))) -> 0 | D3: =Supuestos!$C$17*Supuestos!$C$18*C3 -> 0 | E3: =IF(F3=0,0,IF(D3=0,0.05*Supuestos!$C$18,D3/Supuestos!$C$17)) -> 0 | F3: =IF(A3>=Supuestos!$C$14,1,0) -> 0 | G3: =IF(Supuestos!$C$9*Supuestos!$C$20*E3>0,MAX(Supuestos!$C$25,CEILING(Supuestos!$C$9*Supuestos!$C$20*E3/Supuestos!$C$23,1)+Supuestos!$C$24),Supuestos!$C$25) -> 2 | H3: =IF(Supuestos!$C$9*Supuestos!$C$21*E3>0,MAX(Supuestos!$C$25,CEILING(Supuestos!$C$9*Supuestos!$C$21*E3/Supuestos!$C$23,1)+Supuestos!$C$24),Supuestos!$C$25) -> 2 | I3: =F3*Supuestos!$C$40*(G3+H3)*365*Supuestos!$C$48 -> 0 | J3: =F3*Supuestos!$C$40*60*Supuestos!$C$48 -> 0 | K3: =F3*Supuestos!$C$40*IF(Supuestos!$C$37=0,1,0)*('Precios Azure'!$C$6+MAX(0,Supuestos!$C$46*E3*Supuestos!$C$30/1000000-13)*'Precios Azure'!$C$7) -> 0 | L3: =F3*Supuestos!$C$40*Supuestos!$C$37*730*'Precios Azure'!$C$8 -> 0 | M3: =F3*Supuestos!$C$40*Supuestos!$C$38*730*'Precios Azure'!$C$9 -> 0 | N3: =F3*Supuestos!$C$40*Supuestos!$C$46*E3*(Supuestos!$C$31/1000*'Precios Azure'!$C$10+Supuestos!$C$32/1000*'Precios Azure'!$C$11) -> 0 | O3: =F3*Supuestos!$C$40*((Supuestos!$C$46*E3*Supuestos!$C$22*Supuestos!$C$28/1000*Supuestos!$C$29/30.4+Supuestos!$C$46*E3*Supuestos!$C$33/1000000*Supuestos!$C$34)*'Precios Azure'!$C$12+Supuestos!$C$46*E3*Supuestos!$C$35/10000*'Precios Azure'!$C$13) -> 0 | P3: =F3*Supuestos!$C$40*30.4*'Precios Azure'!$C$5 -> 0 | Q3: =F3*Supuestos!$C$40*MAX(0,Supuestos!$C$36-5)*'Precios Azure'!$C$14 -> 0 | R3: =F3*Supuestos!$C$39*Supuestos!$C$44 -> 0 | S3: =SUM(I3:R3) -> 0 | T3: =D3*Supuestos!$C$19*Supuestos!$C$8 -> 0 | U3: =T3-S3-B3 -> -28020.373 | V3: =SUM($U$2:U3) -> -50820
A4: 3 | B4: =IF(A4=1,Supuestos!$C$11,IF(A4=2,Supuestos!$C$12,IF(A4=3,Supuestos!$C$13,0)))*Supuestos!$C$45 -> 13713.333 | C4: =IF(A4<Supuestos!$C$15,0,IF(A4>=Supuestos!$C$16,1,0.1+0.9*(A4-Supuestos!$C$15)/(Supuestos!$C$16-Supuestos!$C$15))) -> 0 | D4: =Supuestos!$C$17*Supuestos!$C$18*C4 -> 0 | E4: =IF(F4=0,0,IF(D4=0,0.05*Supuestos!$C$18,D4/Supuestos!$C$17)) -> 0 | F4: =IF(A4>=Supuestos!$C$14,1,0) -> 0 | G4: =IF(Supuestos!$C$9*Supuestos!$C$20*E4>0,MAX(Supuestos!$C$25,CEILING(Supuestos!$C$9*Supuestos!$C$20*E4/Supuestos!$C$23,1)+Supuestos!$C$24),Supuestos!$C$25) -> 2 | H4: =IF(Supuestos!$C$9*Supuestos!$C$21*E4>0,MAX(Supuestos!$C$25,CEILING(Supuestos!$C$9*Supuestos!$C$21*E4/Supuestos!$C$23,1)+Supuestos!$C$24),Supuestos!$C$25) -> 2 | I4: =F4*Supuestos!$C$40*(G4+H4)*365*Supuestos!$C$48 -> 0 | J4: =F4*Supuestos!$C$40*60*Supuestos!$C$48 -> 0 | K4: =F4*Supuestos!$C$40*IF(Supuestos!$C$37=0,1,0)*('Precios Azure'!$C$6+MAX(0,Supuestos!$C$46*E4*Supuestos!$C$30/1000000-13)*'Precios Azure'!$C$7) -> 0 | L4: =F4*Supuestos!$C$40*Supuestos!$C$37*730*'Precios Azure'!$C$8 -> 0 | M4: =F4*Supuestos!$C$40*Supuestos!$C$38*730*'Precios Azure'!$C$9 -> 0 | N4: =F4*Supuestos!$C$40*Supuestos!$C$46*E4*(Supuestos!$C$31/1000*'Precios Azure'!$C$10+Supuestos!$C$32/1000*'Precios Azure'!$C$11) -> 0 | O4: =F4*Supuestos!$C$40*((Supuestos!$C$46*E4*Supuestos!$C$22*Supuestos!$C$28/1000*Supuestos!$C$29/30.4+Supuestos!$C$46*E4*Supuestos!$C$33/1000000*Supuestos!$C$34)*'Precios Azure'!$C$12+Supuestos!$C$46*E4*Supuestos!$C$35/10000*'Precios Azure'!$C$13) -> 0 | P4: =F4*Supuestos!$C$40*30.4*'Precios Azure'!$C$5 -> 0 | Q4: =F4*Supuestos!$C$40*MAX(0,Supuestos!$C$36-5)*'Precios Azure'!$C$14 -> 0 | R4: =F4*Supuestos!$C$39*Supuestos!$C$44 -> 0 | S4: =SUM(I4:R4) -> 0 | T4: =D4*Supuestos!$C$19*Supuestos!$C$8 -> 0 | U4: =T4-S4-B4 -> -13713.333 | V4: =SUM($U$2:U4) -> -64533.333
A5: 4 | B5: =IF(A5=1,Supuestos!$C$11,IF(A5=2,Supuestos!$C$12,IF(A5=3,Supuestos!$C$13,0)))*Supuestos!$C$45 -> 0 | C5: =IF(A5<Supuestos!$C$15,0,IF(A5>=Supuestos!$C$16,1,0.1+0.9*(A5-Supuestos!$C$15)/(Supuestos!$C$16-Supuestos!$C$15))) -> 0.1 | D5: =Supuestos!$C$17*Supuestos!$C$18*C5 -> 120 | E5: =IF(F5=0,0,IF(D5=0,0.05*Supuestos!$C$18,D5/Supuestos!$C$17)) -> 0.06 | F5: =IF(A5>=Supuestos!$C$14,1,0) -> 1 | G5: =IF(Supuestos!$C$9*Supuestos!$C$20*E5>0,MAX(Supuestos!$C$25,CEILING(Supuestos!$C$9*Supuestos!$C$20*E5/Supuestos!$C$23,1)+Supuestos!$C$24),Supuestos!$C$25) -> 2 | H5: =IF(Supuestos!$C$9*Supuestos!$C$21*E5>0,MAX(Supuestos!$C$25,CEILING(Supuestos!$C$9*Supuestos!$C$21*E5/Supuestos!$C$23,1)+Supuestos!$C$24),Supuestos!$C$25) -> 2 | I5: =F5*Supuestos!$C$40*(G5+H5)*365*Supuestos!$C$48 -> 166.60595 | J5: =F5*Supuestos!$C$40*60*Supuestos!$C$48 -> 6.8468198 | K5: =F5*Supuestos!$C$40*IF(Supuestos!$C$37=0,1,0)*('Precios Azure'!$C$6+MAX(0,Supuestos!$C$46*E5*Supuestos!$C$30/1000000-13)*'Precios Azure'!$C$7) -> 0 | L5: =F5*Supuestos!$C$40*Supuestos!$C$37*730*'Precios Azure'!$C$8 -> 511.00204 | M5: =F5*Supuestos!$C$40*Supuestos!$C$38*730*'Precios Azure'!$C$9 -> 528.30174 | N5: =F5*Supuestos!$C$40*Supuestos!$C$46*E5*(Supuestos!$C$31/1000*'Precios Azure'!$C$10+Supuestos!$C$32/1000*'Precios Azure'!$C$11) -> 17.4247 | O5: =F5*Supuestos!$C$40*((Supuestos!$C$46*E5*Supuestos!$C$22*Supuestos!$C$28/1000*Supuestos!$C$29/30.4+Supuestos!$C$46*E5*Supuestos!$C$33/1000000*Supuestos!$C$34)*'Precios Azure'!$C$12+Supuestos!$C$46*E5*Supuestos!$C$35/10000*'Precios Azure'!$C$13) -> 10.374809 | P5: =F5*Supuestos!$C$40*30.4*'Precios Azure'!$C$5 -> 3.8223851 | Q5: =F5*Supuestos!$C$40*MAX(0,Supuestos!$C$36-5)*'Precios Azure'!$C$14 -> 119.54765 | R5: =F5*Supuestos!$C$39*Supuestos!$C$44 -> 1466.6667 | S5: =SUM(I5:R5) -> 2830.5928 | T5: =D5*Supuestos!$C$19*Supuestos!$C$8 -> 1440 | U5: =T5-S5-B5 -> -1390.5928 | V5: =SUM($U$2:U5) -> -65923.926
A6: 5 | B6: =IF(A6=1,Supuestos!$C$11,IF(A6=2,Supuestos!$C$12,IF(A6=3,Supuestos!$C$13,0)))*Supuestos!$C$45 -> 0 | C6: =IF(A6<Supuestos!$C$15,0,IF(A6>=Supuestos!$C$16,1,0.1+0.9*(A6-Supuestos!$C$15)/(Supuestos!$C$16-Supuestos!$C$15))) -> 0.18181818 | D6: =Supuestos!$C$17*Supuestos!$C$18*C6 -> 218.18182 | E6: =IF(F6=0,0,IF(D6=0,0.05*Supuestos!$C$18,D6/Supuestos!$C$17)) -> 0.10909091 | F6: =IF(A6>=Supuestos!$C$14,1,0) -> 1 | G6: =IF(Supuestos!$C$9*Supuestos!$C$20*E6>0,MAX(Supuestos!$C$25,CEILING(Supuestos!$C$9*Supuestos!$C$20*E6/Supuestos!$C$23,1)+Supuestos!$C$24),Supuestos!$C$25) -> 2 | H6: =IF(Supuestos!$C$9*Supuestos!$C$21*E6>0,MAX(Supuestos!$C$25,CEILING(Supuestos!$C$9*Supuestos!$C$21*E6/Supuestos!$C$23,1)+Supuestos!$C$24),Supuestos!$C$25) -> 2 | I6: =F6*Supuestos!$C$40*(G6+H6)*365*Supuestos!$C$48 -> 166.60595 | J6: =F6*Supuestos!$C$40*60*Supuestos!$C$48 -> 6.8468198 | K6: =F6*Supuestos!$C$40*IF(Supuestos!$C$37=0,1,0)*('Precios Azure'!$C$6+MAX(0,Supuestos!$C$46*E6*Supuestos!$C$30/1000000-13)*'Precios Azure'!$C$7) -> 0 | L6: =F6*Supuestos!$C$40*Supuestos!$C$37*730*'Precios Azure'!$C$8 -> 511.00204 | M6: =F6*Supuestos!$C$40*Supuestos!$C$38*730*'Precios Azure'!$C$9 -> 528.30174 | N6: =F6*Supuestos!$C$40*Supuestos!$C$46*E6*(Supuestos!$C$31/1000*'Precios Azure'!$C$10+Supuestos!$C$32/1000*'Precios Azure'!$C$11) -> 31.681273 | O6: =F6*Supuestos!$C$40*((Supuestos!$C$46*E6*Supuestos!$C$22*Supuestos!$C$28/1000*Supuestos!$C$29/30.4+Supuestos!$C$46*E6*Supuestos!$C$33/1000000*Supuestos!$C$34)*'Precios Azure'!$C$12+Supuestos!$C$46*E6*Supuestos!$C$35/10000*'Precios Azure'!$C$13) -> 18.86329 | P6: =F6*Supuestos!$C$40*30.4*'Precios Azure'!$C$5 -> 3.8223851 | Q6: =F6*Supuestos!$C$40*MAX(0,Supuestos!$C$36-5)*'Precios Azure'!$C$14 -> 119.54765 | R6: =F6*Supuestos!$C$39*Supuestos!$C$44 -> 1466.6667 | S6: =SUM(I6:R6) -> 2853.3378 | T6: =D6*Supuestos!$C$19*Supuestos!$C$8 -> 2618.1818 | U6: =T6-S6-B6 -> -235.15599 | V6: =SUM($U$2:U6) -> -66159.082
A7: 6 | B7: =IF(A7=1,Supuestos!$C$11,IF(A7=2,Supuestos!$C$12,IF(A7=3,Supuestos!$C$13,0)))*Supuestos!$C$45 -> 0 | C7: =IF(A7<Supuestos!$C$15,0,IF(A7>=Supuestos!$C$16,1,0.1+0.9*(A7-Supuestos!$C$15)/(Supuestos!$C$16-Supuestos!$C$15))) -> 0.26363636 | D7: =Supuestos!$C$17*Supuestos!$C$18*C7 -> 316.36364 | E7: =IF(F7=0,0,IF(D7=0,0.05*Supuestos!$C$18,D7/Supuestos!$C$17)) -> 0.15818182 | F7: =IF(A7>=Supuestos!$C$14,1,0) -> 1 | G7: =IF(Supuestos!$C$9*Supuestos!$C$20*E7>0,MAX(Supuestos!$C$25,CEILING(Supuestos!$C$9*Supuestos!$C$20*E7/Supuestos!$C$23,1)+Supuestos!$C$24),Supuestos!$C$25) -> 2 | H7: =IF(Supuestos!$C$9*Supuestos!$C$21*E7>0,MAX(Supuestos!$C$25,CEILING(Supuestos!$C$9*Supuestos!$C$21*E7/Supuestos!$C$23,1)+Supuestos!$C$24),Supuestos!$C$25) -> 2 | I7: =F7*Supuestos!$C$40*(G7+H7)*365*Supuestos!$C$48 -> 166.60595 | J7: =F7*Supuestos!$C$40*60*Supuestos!$C$48 -> 6.8468198 | K7: =F7*Supuestos!$C$40*IF(Supuestos!$C$37=0,1,0)*('Precios Azure'!$C$6+MAX(0,Supuestos!$C$46*E7*Supuestos!$C$30/1000000-13)*'Precios Azure'!$C$7) -> 0 | L7: =F7*Supuestos!$C$40*Supuestos!$C$37*730*'Precios Azure'!$C$8 -> 511.00204 | M7: =F7*Supuestos!$C$40*Supuestos!$C$38*730*'Precios Azure'!$C$9 -> 528.30174 | N7: =F7*Supuestos!$C$40*Supuestos!$C$46*E7*(Supuestos!$C$31/1000*'Precios Azure'!$C$10+Supuestos!$C$32/1000*'Precios Azure'!$C$11) -> 45.937846 | O7: =F7*Supuestos!$C$40*((Supuestos!$C$46*E7*Supuestos!$C$22*Supuestos!$C$28/1000*Supuestos!$C$29/30.4+Supuestos!$C$46*E7*Supuestos!$C$33/1000000*Supuestos!$C$34)*'Precios Azure'!$C$12+Supuestos!$C$46*E7*Supuestos!$C$35/10000*'Precios Azure'!$C$13) -> 27.35177 | P7: =F7*Supuestos!$C$40*30.4*'Precios Azure'!$C$5 -> 3.8223851 | Q7: =F7*Supuestos!$C$40*MAX(0,Supuestos!$C$36-5)*'Precios Azure'!$C$14 -> 119.54765 | R7: =F7*Supuestos!$C$39*Supuestos!$C$44 -> 1466.6667 | S7: =SUM(I7:R7) -> 2876.0829 | T7: =D7*Supuestos!$C$19*Supuestos!$C$8 -> 3796.3636 | U7: =T7-S7-B7 -> 920.28077 | V7: =SUM($U$2:U7) -> -65238.801
A8: 7 | B8: =IF(A8=1,Supuestos!$C$11,IF(A8=2,Supuestos!$C$12,IF(A8=3,Supuestos!$C$13,0)))*Supuestos!$C$45 -> 0 | C8: =IF(A8<Supuestos!$C$15,0,IF(A8>=Supuestos!$C$16,1,0.1+0.9*(A8-Supuestos!$C$15)/(Supuestos!$C$16-Supuestos!$C$15))) -> 0.34545455 | D8: =Supuestos!$C$17*Supuestos!$C$18*C8 -> 414.54545 | E8: =IF(F8=0,0,IF(D8=0,0.05*Supuestos!$C$18,D8/Supuestos!$C$17)) -> 0.20727273 | F8: =IF(A8>=Supuestos!$C$14,1,0) -> 1 | G8: =IF(Supuestos!$C$9*Supuestos!$C$20*E8>0,MAX(Supuestos!$C$25,CEILING(Supuestos!$C$9*Supuestos!$C$20*E8/Supuestos!$C$23,1)+Supuestos!$C$24),Supuestos!$C$25) -> 2 | H8: =IF(Supuestos!$C$9*Supuestos!$C$21*E8>0,MAX(Supuestos!$C$25,CEILING(Supuestos!$C$9*Supuestos!$C$21*E8/Supuestos!$C$23,1)+Supuestos!$C$24),Supuestos!$C$25) -> 2 | I8: =F8*Supuestos!$C$40*(G8+H8)*365*Supuestos!$C$48 -> 166.60595 | J8: =F8*Supuestos!$C$40*60*Supuestos!$C$48 -> 6.8468198 | K8: =F8*Supuestos!$C$40*IF(Supuestos!$C$37=0,1,0)*('Precios Azure'!$C$6+MAX(0,Supuestos!$C$46*E8*Supuestos!$C$30/1000000-13)*'Precios Azure'!$C$7) -> 0 | L8: =F8*Supuestos!$C$40*Supuestos!$C$37*730*'Precios Azure'!$C$8 -> 511.00204 | M8: =F8*Supuestos!$C$40*Supuestos!$C$38*730*'Precios Azure'!$C$9 -> 528.30174 | N8: =F8*Supuestos!$C$40*Supuestos!$C$46*E8*(Supuestos!$C$31/1000*'Precios Azure'!$C$10+Supuestos!$C$32/1000*'Precios Azure'!$C$11) -> 60.194419 | O8: =F8*Supuestos!$C$40*((Supuestos!$C$46*E8*Supuestos!$C$22*Supuestos!$C$28/1000*Supuestos!$C$29/30.4+Supuestos!$C$46*E8*Supuestos!$C$33/1000000*Supuestos!$C$34)*'Precios Azure'!$C$12+Supuestos!$C$46*E8*Supuestos!$C$35/10000*'Precios Azure'!$C$13) -> 35.84025 | P8: =F8*Supuestos!$C$40*30.4*'Precios Azure'!$C$5 -> 3.8223851 | Q8: =F8*Supuestos!$C$40*MAX(0,Supuestos!$C$36-5)*'Precios Azure'!$C$14 -> 119.54765 | R8: =F8*Supuestos!$C$39*Supuestos!$C$44 -> 1466.6667 | S8: =SUM(I8:R8) -> 2898.8279 | T8: =D8*Supuestos!$C$19*Supuestos!$C$8 -> 4974.5455 | U8: =T8-S8-B8 -> 2075.7175 | V8: =SUM($U$2:U8) -> -63163.084
A9: 8 | B9: =IF(A9=1,Supuestos!$C$11,IF(A9=2,Supuestos!$C$12,IF(A9=3,Supuestos!$C$13,0)))*Supuestos!$C$45 -> 0 | C9: =IF(A9<Supuestos!$C$15,0,IF(A9>=Supuestos!$C$16,1,0.1+0.9*(A9-Supuestos!$C$15)/(Supuestos!$C$16-Supuestos!$C$15))) -> 0.42727273 | D9: =Supuestos!$C$17*Supuestos!$C$18*C9 -> 512.72727 | E9: =IF(F9=0,0,IF(D9=0,0.05*Supuestos!$C$18,D9/Supuestos!$C$17)) -> 0.25636364 | F9: =IF(A9>=Supuestos!$C$14,1,0) -> 1 | G9: =IF(Supuestos!$C$9*Supuestos!$C$20*E9>0,MAX(Supuestos!$C$25,CEILING(Supuestos!$C$9*Supuestos!$C$20*E9/Supuestos!$C$23,1)+Supuestos!$C$24),Supuestos!$C$25) -> 3 | H9: =IF(Supuestos!$C$9*Supuestos!$C$21*E9>0,MAX(Supuestos!$C$25,CEILING(Supuestos!$C$9*Supuestos!$C$21*E9/Supuestos!$C$23,1)+Supuestos!$C$24),Supuestos!$C$25) -> 2 | I9: =F9*Supuestos!$C$40*(G9+H9)*365*Supuestos!$C$48 -> 208.25744 | J9: =F9*Supuestos!$C$40*60*Supuestos!$C$48 -> 6.8468198 | K9: =F9*Supuestos!$C$40*IF(Supuestos!$C$37=0,1,0)*('Precios Azure'!$C$6+MAX(0,Supuestos!$C$46*E9*Supuestos!$C$30/1000000-13)*'Precios Azure'!$C$7) -> 0 | L9: =F9*Supuestos!$C$40*Supuestos!$C$37*730*'Precios Azure'!$C$8 -> 511.00204 | M9: =F9*Supuestos!$C$40*Supuestos!$C$38*730*'Precios Azure'!$C$9 -> 528.30174 | N9: =F9*Supuestos!$C$40*Supuestos!$C$46*E9*(Supuestos!$C$31/1000*'Precios Azure'!$C$10+Supuestos!$C$32/1000*'Precios Azure'!$C$11) -> 74.450992 | O9: =F9*Supuestos!$C$40*((Supuestos!$C$46*E9*Supuestos!$C$22*Supuestos!$C$28/1000*Supuestos!$C$29/30.4+Supuestos!$C$46*E9*Supuestos!$C$33/1000000*Supuestos!$C$34)*'Precios Azure'!$C$12+Supuestos!$C$46*E9*Supuestos!$C$35/10000*'Precios Azure'!$C$13) -> 44.32873 | P9: =F9*Supuestos!$C$40*30.4*'Precios Azure'!$C$5 -> 3.8223851 | Q9: =F9*Supuestos!$C$40*MAX(0,Supuestos!$C$36-5)*'Precios Azure'!$C$14 -> 119.54765 | R9: =F9*Supuestos!$C$39*Supuestos!$C$44 -> 1466.6667 | S9: =SUM(I9:R9) -> 2963.2245 | T9: =D9*Supuestos!$C$19*Supuestos!$C$8 -> 6152.7273 | U9: =T9-S9-B9 -> 3189.5028 | V9: =SUM($U$2:U9) -> -59973.581
A10: 9 | B10: =IF(A10=1,Supuestos!$C$11,IF(A10=2,Supuestos!$C$12,IF(A10=3,Supuestos!$C$13,0)))*Supuestos!$C$45 -> 0 | C10: =IF(A10<Supuestos!$C$15,0,IF(A10>=Supuestos!$C$16,1,0.1+0.9*(A10-Supuestos!$C$15)/(Supuestos!$C$16-Supuestos!$C$15))) -> 0.50909091 | D10: =Supuestos!$C$17*Supuestos!$C$18*C10 -> 610.90909 | E10: =IF(F10=0,0,IF(D10=0,0.05*Supuestos!$C$18,D10/Supuestos!$C$17)) -> 0.30545455 | F10: =IF(A10>=Supuestos!$C$14,1,0) -> 1 | G10: =IF(Supuestos!$C$9*Supuestos!$C$20*E10>0,MAX(Supuestos!$C$25,CEILING(Supuestos!$C$9*Supuestos!$C$20*E10/Supuestos!$C$23,1)+Supuestos!$C$24),Supuestos!$C$25) -> 3 | H10: =IF(Supuestos!$C$9*Supuestos!$C$21*E10>0,MAX(Supuestos!$C$25,CEILING(Supuestos!$C$9*Supuestos!$C$21*E10/Supuestos!$C$23,1)+Supuestos!$C$24),Supuestos!$C$25) -> 2 | I10: =F10*Supuestos!$C$40*(G10+H10)*365*Supuestos!$C$48 -> 208.25744 | J10: =F10*Supuestos!$C$40*60*Supuestos!$C$48 -> 6.8468198 | K10: =F10*Supuestos!$C$40*IF(Supuestos!$C$37=0,1,0)*('Precios Azure'!$C$6+MAX(0,Supuestos!$C$46*E10*Supuestos!$C$30/1000000-13)*'Precios Azure'!$C$7) -> 0 | L10: =F10*Supuestos!$C$40*Supuestos!$C$37*730*'Precios Azure'!$C$8 -> 511.00204 | M10: =F10*Supuestos!$C$40*Supuestos!$C$38*730*'Precios Azure'!$C$9 -> 528.30174 | N10: =F10*Supuestos!$C$40*Supuestos!$C$46*E10*(Supuestos!$C$31/1000*'Precios Azure'!$C$10+Supuestos!$C$32/1000*'Precios Azure'!$C$11) -> 88.707565 | O10: =F10*Supuestos!$C$40*((Supuestos!$C$46*E10*Supuestos!$C$22*Supuestos!$C$28/1000*Supuestos!$C$29/30.4+Supuestos!$C$46*E10*Supuestos!$C$33/1000000*Supuestos!$C$34)*'Precios Azure'!$C$12+Supuestos!$C$46*E10*Supuestos!$C$35/10000*'Precios Azure'!$C$13) -> 52.817211 | P10: =F10*Supuestos!$C$40*30.4*'Precios Azure'!$C$5 -> 3.8223851 | Q10: =F10*Supuestos!$C$40*MAX(0,Supuestos!$C$36-5)*'Precios Azure'!$C$14 -> 119.54765 | R10: =F10*Supuestos!$C$39*Supuestos!$C$44 -> 1466.6667 | S10: =SUM(I10:R10) -> 2985.9695 | T10: =D10*Supuestos!$C$19*Supuestos!$C$8 -> 7330.9091 | U10: =T10-S10-B10 -> 4344.9396 | V10: =SUM($U$2:U10) -> -55628.641
A11: 10 | B11: =IF(A11=1,Supuestos!$C$11,IF(A11=2,Supuestos!$C$12,IF(A11=3,Supuestos!$C$13,0)))*Supuestos!$C$45 -> 0 | C11: =IF(A11<Supuestos!$C$15,0,IF(A11>=Supuestos!$C$16,1,0.1+0.9*(A11-Supuestos!$C$15)/(Supuestos!$C$16-Supuestos!$C$15))) -> 0.59090909 | D11: =Supuestos!$C$17*Supuestos!$C$18*C11 -> 709.09091 | E11: =IF(F11=0,0,IF(D11=0,0.05*Supuestos!$C$18,D11/Supuestos!$C$17)) -> 0.35454545 | F11: =IF(A11>=Supuestos!$C$14,1,0) -> 1 | G11: =IF(Supuestos!$C$9*Supuestos!$C$20*E11>0,MAX(Supuestos!$C$25,CEILING(Supuestos!$C$9*Supuestos!$C$20*E11/Supuestos!$C$23,1)+Supuestos!$C$24),Supuestos!$C$25) -> 3 | H11: =IF(Supuestos!$C$9*Supuestos!$C$21*E11>0,MAX(Supuestos!$C$25,CEILING(Supuestos!$C$9*Supuestos!$C$21*E11/Supuestos!$C$23,1)+Supuestos!$C$24),Supuestos!$C$25) -> 2 | I11: =F11*Supuestos!$C$40*(G11+H11)*365*Supuestos!$C$48 -> 208.25744 | J11: =F11*Supuestos!$C$40*60*Supuestos!$C$48 -> 6.8468198 | K11: =F11*Supuestos!$C$40*IF(Supuestos!$C$37=0,1,0)*('Precios Azure'!$C$6+MAX(0,Supuestos!$C$46*E11*Supuestos!$C$30/1000000-13)*'Precios Azure'!$C$7) -> 0 | L11: =F11*Supuestos!$C$40*Supuestos!$C$37*730*'Precios Azure'!$C$8 -> 511.00204 | M11: =F11*Supuestos!$C$40*Supuestos!$C$38*730*'Precios Azure'!$C$9 -> 528.30174 | N11: =F11*Supuestos!$C$40*Supuestos!$C$46*E11*(Supuestos!$C$31/1000*'Precios Azure'!$C$10+Supuestos!$C$32/1000*'Precios Azure'!$C$11) -> 102.96414 | O11: =F11*Supuestos!$C$40*((Supuestos!$C$46*E11*Supuestos!$C$22*Supuestos!$C$28/1000*Supuestos!$C$29/30.4+Supuestos!$C$46*E11*Supuestos!$C$33/1000000*Supuestos!$C$34)*'Precios Azure'!$C$12+Supuestos!$C$46*E11*Supuestos!$C$35/10000*'Precios Azure'!$C$13) -> 61.305691 | P11: =F11*Supuestos!$C$40*30.4*'Precios Azure'!$C$5 -> 3.8223851 | Q11: =F11*Supuestos!$C$40*MAX(0,Supuestos!$C$36-5)*'Precios Azure'!$C$14 -> 119.54765 | R11: =F11*Supuestos!$C$39*Supuestos!$C$44 -> 1466.6667 | S11: =SUM(I11:R11) -> 3008.7146 | T11: =D11*Supuestos!$C$19*Supuestos!$C$8 -> 8509.0909 | U11: =T11-S11-B11 -> 5500.3763 | V11: =SUM($U$2:U11) -> -50128.265
A12: 11 | B12: =IF(A12=1,Supuestos!$C$11,IF(A12=2,Supuestos!$C$12,IF(A12=3,Supuestos!$C$13,0)))*Supuestos!$C$45 -> 0 | C12: =IF(A12<Supuestos!$C$15,0,IF(A12>=Supuestos!$C$16,1,0.1+0.9*(A12-Supuestos!$C$15)/(Supuestos!$C$16-Supuestos!$C$15))) -> 0.67272727 | D12: =Supuestos!$C$17*Supuestos!$C$18*C12 -> 807.27273 | E12: =IF(F12=0,0,IF(D12=0,0.05*Supuestos!$C$18,D12/Supuestos!$C$17)) -> 0.40363636 | F12: =IF(A12>=Supuestos!$C$14,1,0) -> 1 | G12: =IF(Supuestos!$C$9*Supuestos!$C$20*E12>0,MAX(Supuestos!$C$25,CEILING(Supuestos!$C$9*Supuestos!$C$20*E12/Supuestos!$C$23,1)+Supuestos!$C$24),Supuestos!$C$25) -> 3 | H12: =IF(Supuestos!$C$9*Supuestos!$C$21*E12>0,MAX(Supuestos!$C$25,CEILING(Supuestos!$C$9*Supuestos!$C$21*E12/Supuestos!$C$23,1)+Supuestos!$C$24),Supuestos!$C$25) -> 2 | I12: =F12*Supuestos!$C$40*(G12+H12)*365*Supuestos!$C$48 -> 208.25744 | J12: =F12*Supuestos!$C$40*60*Supuestos!$C$48 -> 6.8468198 | K12: =F12*Supuestos!$C$40*IF(Supuestos!$C$37=0,1,0)*('Precios Azure'!$C$6+MAX(0,Supuestos!$C$46*E12*Supuestos!$C$30/1000000-13)*'Precios Azure'!$C$7) -> 0 | L12: =F12*Supuestos!$C$40*Supuestos!$C$37*730*'Precios Azure'!$C$8 -> 511.00204 | M12: =F12*Supuestos!$C$40*Supuestos!$C$38*730*'Precios Azure'!$C$9 -> 528.30174 | N12: =F12*Supuestos!$C$40*Supuestos!$C$46*E12*(Supuestos!$C$31/1000*'Precios Azure'!$C$10+Supuestos!$C$32/1000*'Precios Azure'!$C$11) -> 117.22071 | O12: =F12*Supuestos!$C$40*((Supuestos!$C$46*E12*Supuestos!$C$22*Supuestos!$C$28/1000*Supuestos!$C$29/30.4+Supuestos!$C$46*E12*Supuestos!$C$33/1000000*Supuestos!$C$34)*'Precios Azure'!$C$12+Supuestos!$C$46*E12*Supuestos!$C$35/10000*'Precios Azure'!$C$13) -> 69.794171 | P12: =F12*Supuestos!$C$40*30.4*'Precios Azure'!$C$5 -> 3.8223851 | Q12: =F12*Supuestos!$C$40*MAX(0,Supuestos!$C$36-5)*'Precios Azure'!$C$14 -> 119.54765 | R12: =F12*Supuestos!$C$39*Supuestos!$C$44 -> 1466.6667 | S12: =SUM(I12:R12) -> 3031.4596 | T12: =D12*Supuestos!$C$19*Supuestos!$C$8 -> 9687.2727 | U12: =T12-S12-B12 -> 6655.8131 | V12: =SUM($U$2:U12) -> -43472.452
A13: 12 | B13: =IF(A13=1,Supuestos!$C$11,IF(A13=2,Supuestos!$C$12,IF(A13=3,Supuestos!$C$13,0)))*Supuestos!$C$45 -> 0 | C13: =IF(A13<Supuestos!$C$15,0,IF(A13>=Supuestos!$C$16,1,0.1+0.9*(A13-Supuestos!$C$15)/(Supuestos!$C$16-Supuestos!$C$15))) -> 0.75454545 | D13: =Supuestos!$C$17*Supuestos!$C$18*C13 -> 905.45455 | E13: =IF(F13=0,0,IF(D13=0,0.05*Supuestos!$C$18,D13/Supuestos!$C$17)) -> 0.45272727 | F13: =IF(A13>=Supuestos!$C$14,1,0) -> 1 | G13: =IF(Supuestos!$C$9*Supuestos!$C$20*E13>0,MAX(Supuestos!$C$25,CEILING(Supuestos!$C$9*Supuestos!$C$20*E13/Supuestos!$C$23,1)+Supuestos!$C$24),Supuestos!$C$25) -> 3 | H13: =IF(Supuestos!$C$9*Supuestos!$C$21*E13>0,MAX(Supuestos!$C$25,CEILING(Supuestos!$C$9*Supuestos!$C$21*E13/Supuestos!$C$23,1)+Supuestos!$C$24),Supuestos!$C$25) -> 2 | I13: =F13*Supuestos!$C$40*(G13+H13)*365*Supuestos!$C$48 -> 208.25744 | J13: =F13*Supuestos!$C$40*60*Supuestos!$C$48 -> 6.8468198 | K13: =F13*Supuestos!$C$40*IF(Supuestos!$C$37=0,1,0)*('Precios Azure'!$C$6+MAX(0,Supuestos!$C$46*E13*Supuestos!$C$30/1000000-13)*'Precios Azure'!$C$7) -> 0 | L13: =F13*Supuestos!$C$40*Supuestos!$C$37*730*'Precios Azure'!$C$8 -> 511.00204 | M13: =F13*Supuestos!$C$40*Supuestos!$C$38*730*'Precios Azure'!$C$9 -> 528.30174 | N13: =F13*Supuestos!$C$40*Supuestos!$C$46*E13*(Supuestos!$C$31/1000*'Precios Azure'!$C$10+Supuestos!$C$32/1000*'Precios Azure'!$C$11) -> 131.47728 | O13: =F13*Supuestos!$C$40*((Supuestos!$C$46*E13*Supuestos!$C$22*Supuestos!$C$28/1000*Supuestos!$C$29/30.4+Supuestos!$C$46*E13*Supuestos!$C$33/1000000*Supuestos!$C$34)*'Precios Azure'!$C$12+Supuestos!$C$46*E13*Supuestos!$C$35/10000*'Precios Azure'!$C$13) -> 78.282651 | P13: =F13*Supuestos!$C$40*30.4*'Precios Azure'!$C$5 -> 3.8223851 | Q13: =F13*Supuestos!$C$40*MAX(0,Supuestos!$C$36-5)*'Precios Azure'!$C$14 -> 119.54765 | R13: =F13*Supuestos!$C$39*Supuestos!$C$44 -> 1466.6667 | S13: =SUM(I13:R13) -> 3054.2047 | T13: =D13*Supuestos!$C$19*Supuestos!$C$8 -> 10865.455 | U13: =T13-S13-B13 -> 7811.2499 | V13: =SUM($U$2:U13) -> -35661.202
... A37: 36 | B37: =IF(A37=1,Supuestos!$C$11,IF(A37=2,Supuestos!$C$12,IF(A37=3,Supuestos!$C$13,0)))*Supuestos!$C$45 -> 0 | C37: =IF(A37<Supuestos!$C$15,0,IF(A37>=Supuestos!$C$16,1,0.1+0.9*(A37-Supuestos!$C$15)/(Supuestos!$C$16-Supuestos!$C$15))) -> 1 | D37: =Supuestos!$C$17*Supuestos!$C$18*C37 -> 1200 | E37: =IF(F37=0,0,IF(D37=0,0.05*Supuestos!$C$18,D37/Supuestos!$C$17)) -> 0.6 | F37: =IF(A37>=Supuestos!$C$14,1,0) -> 1 | G37: =IF(Supuestos!$C$9*Supuestos!$C$20*E37>0,MAX(Supuestos!$C$25,CEILING(Supuestos!$C$9*Supuestos!$C$20*E37/Supuestos!$C$23,1)+Supuestos!$C$24),Supuestos!$C$25) -> 4 | H37: =IF(Supuestos!$C$9*Supuestos!$C$21*E37>0,MAX(Supuestos!$C$25,CEILING(Supuestos!$C$9*Supuestos!$C$21*E37/Supuestos!$C$23,1)+Supuestos!$C$24),Supuestos!$C$25) -> 2 | I37: =F37*Supuestos!$C$40*(G37+H37)*365*Supuestos!$C$48 -> 249.90892 | J37: =F37*Supuestos!$C$40*60*Supuestos!$C$48 -> 6.8468198 | K37: =F37*Supuestos!$C$40*IF(Supuestos!$C$37=0,1,0)*('Precios Azure'!$C$6+MAX(0,Supuestos!$C$46*E37*Supuestos!$C$30/1000000-13)*'Precios Azure'!$C$7) -> 0 | L37: =F37*Supuestos!$C$40*Supuestos!$C$37*730*'Precios Azure'!$C$8 -> 511.00204 | M37: =F37*Supuestos!$C$40*Supuestos!$C$38*730*'Precios Azure'!$C$9 -> 528.30174 | N37: =F37*Supuestos!$C$40*Supuestos!$C$46*E37*(Supuestos!$C$31/1000*'Precios Azure'!$C$10+Supuestos!$C$32/1000*'Precios Azure'!$C$11) -> 174.247 | O37: =F37*Supuestos!$C$40*((Supuestos!$C$46*E37*Supuestos!$C$22*Supuestos!$C$28/1000*Supuestos!$C$29/30.4+Supuestos!$C$46*E37*Supuestos!$C$33/1000000*Supuestos!$C$34)*'Precios Azure'!$C$12+Supuestos!$C$46*E37*Supuestos!$C$35/10000*'Precios Azure'!$C$13) -> 103.74809 | P37: =F37*Supuestos!$C$40*30.4*'Precios Azure'!$C$5 -> 3.8223851 | Q37: =F37*Supuestos!$C$40*MAX(0,Supuestos!$C$36-5)*'Precios Azure'!$C$14 -> 119.54765 | R37: =F37*Supuestos!$C$39*Supuestos!$C$44 -> 1466.6667 | S37: =SUM(I37:R37) -> 3164.0913 | T37: =D37*Supuestos!$C$19*Supuestos!$C$8 -> 14400 | U37: =T37-S37-B37 -> 11235.909 | V37: =SUM($U$2:U37) -> 230534.3

Sheet Flujo Pesimista
A1: Mes | B1: CAPEX | C1: Curva adopción | D1: Puestos con módulo | E1: Uso relativo | F1: En operación | G1: Réplicas horario hábil | H1: Réplicas fuera de horario | I1: API inferencia | J1: Jobs batch | K1: Service Bus Std | L1: Service Bus Premium | M1: APIM | N1: Azure OpenAI | O1: Blob (audio + resultados) | P1: Container Registry | Q1: Log Analytics | R1: MLOps | S1: OPEX total | T1: Ingresos (recargo) | U1: Flujo neto | V1: Flujo acumulado
